Workbook

Sheet Hoja1
D1: Radiación Global Mensual en plano Horizontal (kWh/m^2/día) | P1: Temperatura media mensual (°C)
A2: Ciudad | B2: Longitud (º) | C2: Latitud (º) | D2: Enero | E2: Febrero | F2: Marzo | G2: Abril | H2: Mayo | I2: Junio | J2: Julio | K2: Agosto | L2: Septiembre | M2: Octubre | N2: Noviembre | O2: Diciembre | P2: Enero | Q2: Febrero | R2: Marzo | S2: Abril | T2: Mayo | U2: Junio | V2: Julio | W2: Agosto | X2: Septiembre | Y2: Octubre | Z2: Noviembre | AA2: Diciembre
A3: Albacete | B3: =-(1+51/60+36/3600) -> -1.86 | C3: =38+(59/60)+(51/3600) -> 38.9975 | D3: =Hoja2!D3/Hoja2!$B$105 -> 2.33 | E3: =Hoja2!E3/Hoja2!$B$105 -> 3.06 | F3: =Hoja2!F3/Hoja2!$B$105 -> 4.46 | G3: =Hoja2!G3/Hoja2!$B$105 -> 5.33 | H3: =Hoja2!H3/Hoja2!$B$105 -> 6.48 | I3: =Hoja2!I3/Hoja2!$B$105 -> 7.06 | J3: =Hoja2!J3/Hoja2!$B$105 -> 7.09 | K3: =Hoja2!K3/Hoja2!$B$105 -> 6.28 | ... O3: =Hoja2!O3/Hoja2!$B$105 -> 2 | P3: 5.2 | Q3: 6.5 | R3: 9.4 | S3: 12.2 | T3: 16 | U3: 21.2 | V3: 24.2 | W3: 24 | X3: 19.4 | Y3: 15.1 | Z3: 9 | AA3: 6.2 | AB3: PVGIS - Classic
A4: Alicante | B4: =-(0+28/60+51/3600) -> -0.48083333 | C4: =38+(20/60)+(42/3600) -> 38.345 | D4: =Hoja2!D4/Hoja2!$B$105 -> 2.32 | E4: =Hoja2!E4/Hoja2!$B$105 -> 3.09 | F4: =Hoja2!F4/Hoja2!$B$105 -> 4.34 | G4: =Hoja2!G4/Hoja2!$B$105 -> 5.26 | H4: =Hoja2!H4/Hoja2!$B$105 -> 6.37 | I4: =Hoja2!I4/Hoja2!$B$105 -> 6.89 | J4: =Hoja2!J4/Hoja2!$B$105 -> 6.91 | K4: =Hoja2!K4/Hoja2!$B$105 -> 6.09 | ... O4: =Hoja2!O4/Hoja2!$B$105 -> 2.07 | P4: 12.4 | Q4: 12.8 | R4: 13.8 | S4: 15 | T4: 17.6 | U4: 20.9 | V4: 23.5 | W4: 24.2 | X4: 23 | Y4: 20.1 | Z4: 15.7 | AA4: 13.8
A5: Almería | B5: =-(2+28/60+4/3600) -> -2.4677778 | C5: =36+(50/60)+(24/3600) -> 36.84 | D5: =Hoja2!D5/Hoja2!$B$105 -> 2.49 | E5: =Hoja2!E5/Hoja2!$B$105 -> 3.21 | F5: =Hoja2!F5/Hoja2!$B$105 -> 4.47 | G5: =Hoja2!G5/Hoja2!$B$105 -> 5.29 | H5: =Hoja2!H5/Hoja2!$B$105 -> 6.42 | I5: =Hoja2!I5/Hoja2!$B$105 -> 6.94 | J5: =Hoja2!J5/Hoja2!$B$105 -> 6.89 | K5: =Hoja2!K5/Hoja2!$B$105 -> 6.05 | ... O5: =Hoja2!O5/Hoja2!$B$105 -> 2.18 | P5: 13.6 | Q5: 13.6 | R5: 14.9 | S5: 16.3 | T5: 18.6 | U5: 21.6 | V5: 24.3 | W5: 25 | X5: 23.3 | Y5: 20.4 | Z5: 16.6 | AA5: 14.6
A6: Ávila | B6: =-(4+42/60+1/3600) -> -4.7002778 | C6: =40+39/60+23/3600 -> 40.656389 | D6: =Hoja2!D6/Hoja2!$B$105 -> 2 | E6: =Hoja2!E6/Hoja2!$B$105 -> 2.78 | F6: =Hoja2!F6/Hoja2!$B$105 -> 4.56 | G6: =Hoja2!G6/Hoja2!$B$105 -> 5.24 | H6: =Hoja2!H6/Hoja2!$B$105 -> 6.59 | I6: =Hoja2!I6/Hoja2!$B$105 -> 7.28 | J6: =Hoja2!J6/Hoja2!$B$105 -> 7.39 | K6: =Hoja2!K6/Hoja2!$B$105 -> 6.55 | ... O6: =Hoja2!O6/Hoja2!$B$105 -> 1.6 | P6: 2.4 | Q6: 3.1 | R6: 6 | S6: 8.4 | T6: 12.6 | U6: 18.4 | V6: 21.1 | W6: 20.9 | X6: 16.9 | Y6: 11.4 | Z6: 5.5 | AA6: 3.1
A7: Badajoz | B7: =-(6+58/60+12/3600) -> -6.97 | C7: =38+52/60+42/3600 -> 38.878333 | D7: =Hoja2!D7/Hoja2!$B$105 -> 2.23 | E7: =Hoja2!E7/Hoja2!$B$105 -> 2.88 | F7: =Hoja2!F7/Hoja2!$B$105 -> 4.72 | G7: =Hoja2!G7/Hoja2!$B$105 -> 5.13 | H7: =Hoja2!H7/Hoja2!$B$105 -> 6.61 | I7: =Hoja2!I7/Hoja2!$B$105 -> 7.25 | J7: =Hoja2!J7/Hoja2!$B$105 -> 7.22 | K7: =Hoja2!K7/Hoja2!$B$105 -> 6.65 | ... O7: =Hoja2!O7/Hoja2!$B$105 -> 1.93 | P7: 8.2 | Q7: 9.5 | R7: 12.4 | S7: 14.6 | T7: 18.7 | U7: 23.8 | V7: 25.9 | W7: 26.2 | X7: 22.7 | Y7: 17.7 | Z7: 11.8 | AA7: 8.9
A8: Barcelona | B8: =(2+10/60+11/3600) -> 2.1697222 | C8: =41+23/60+16/3600 -> 41.387778 | D8: =Hoja2!D8/Hoja2!$B$105 -> 1.89 | E8: =Hoja2!E8/Hoja2!$B$105 -> 2.56 | F8: =Hoja2!F8/Hoja2!$B$105 -> 3.91 | G8: =Hoja2!G8/Hoja2!$B$105 -> 4.9 | H8: =Hoja2!H8/Hoja2!$B$105 -> 5.84 | I8: =Hoja2!I8/Hoja2!$B$105 -> 6.55 | J8: =Hoja2!J8/Hoja2!$B$105 -> 6.58 | K8: =Hoja2!K8/Hoja2!$B$105 -> 5.78 | ... O8: =Hoja2!O8/Hoja2!$B$105 -> 1.68 | P8: 9.9 | Q8: 10.1 | R8: 12 | S8: 14.1 | T8: 16.9 | U8: 20.9 | V8: 23.5 | W8: 24.4 | X8: 21.8 | Y8: 18.8 | Z8: 14.1 | AA8: 10.9
A9: Bilbao | B9: =-(2+55/60+24/3600) -> -2.9233333 | C9: =43+15/60+2/3600 -> 43.250556 | D9: =Hoja2!D9/Hoja2!$B$105 -> 1.43 | E9: =Hoja2!E9/Hoja2!$B$105 -> 2.12 | F9: =Hoja2!F9/Hoja2!$B$105 -> 3.5 | G9: =Hoja2!G9/Hoja2!$B$105 -> 4.3 | H9: =Hoja2!H9/Hoja2!$B$105 -> 5.3 | I9: =Hoja2!I9/Hoja2!$B$105 -> 5.86 | J9: =Hoja2!J9/Hoja2!$B$105 -> 5.84 | K9: =Hoja2!K9/Hoja2!$B$105 -> 5.14 | ... O9: =Hoja2!O9/Hoja2!$B$105 -> 1.23 | P9: 7.2 | Q9: 8 | R9: 10.8 | S9: 12.3 | T9: 15.3 | U9: 18.4 | V9: 19.9 | W9: 20.4 | X9: 18.5 | Y9: 15.9 | Z9: 10.9 | AA9: 8
A10: Burgos | B10: =-(3+41/60+59/3600) -> -3.6997222 | C10: =42+20/60+27/3600 -> 42.340833 | D10: =Hoja2!D10/Hoja2!$B$105 -> 1.7 | E10: =Hoja2!E10/Hoja2!$B$105 -> 2.53 | F10: =Hoja2!F10/Hoja2!$B$105 -> 4.06 | G10: =Hoja2!G10/Hoja2!$B$105 -> 4.88 | H10: =Hoja2!H10/Hoja2!$B$105 -> 6.01 | I10: =Hoja2!I10/Hoja2!$B$105 -> 6.67 | J10: =Hoja2!J10/Hoja2!$B$105 -> 6.75 | K10: =Hoja2!K10/Hoja2!$B$105 -> 5.9 | ... O10: =Hoja2!O10/Hoja2!$B$105 -> 1.37 | P10: 3.1 | Q10: 3.7 | R10: 6.9 | S10: 8.6 | T10: 12.3 | U10: 17 | V10: 19.2 | W10: 19.5 | X10: 16.3 | Y10: 11.9 | Z10: 6.4 | AA10: 3.6
A11: Cáceres | B11: =-(6+22/60+14/3600) -> -6.3705556 | C11: =39+28/60+34/3600 -> 39.476111 | D11: =Hoja2!D11/Hoja2!$B$105 -> 2.12 | E11: =Hoja2!E11/Hoja2!$B$105 -> 2.81 | F11: =Hoja2!F11/Hoja2!$B$105 -> 4.62 | G11: =Hoja2!G11/Hoja2!$B$105 -> 5.01 | H11: =Hoja2!H11/Hoja2!$B$105 -> 6.48 | I11: =Hoja2!I11/Hoja2!$B$105 -> 7.2 | J11: =Hoja2!J11/Hoja2!$B$105 -> 7.18 | K11: =Hoja2!K11/Hoja2!$B$105 -> 6.56 | ... O11: =Hoja2!O11/Hoja2!$B$105 -> 1.77 | P11: 6.9 | Q11: 8.1 | R11: 10.8 | S11: 13.1 | T11: 17 | U11: 22.3 | V11: 24.8 | W11: 24.9 | X11: 21.2 | Y11: 16.2 | Z11: 10.2 | AA11: 7.5
A12: Cádiz | B12: =-(6+17/60+33/3600) -> -6.2925 | C12: =36+31/60+46/3600 -> 36.529444 | D12: =Hoja2!D12/Hoja2!$B$105 -> 2.55 | E12: =Hoja2!E12/Hoja2!$B$105 -> 3.16 | F12: =Hoja2!F12/Hoja2!$B$105 -> 4.59 | G12: =Hoja2!G12/Hoja2!$B$105 -> 5.4 | H12: =Hoja2!H12/Hoja2!$B$105 -> 6.76 | I12: =Hoja2!I12/Hoja2!$B$105 -> 7.28 | J12: =Hoja2!J12/Hoja2!$B$105 -> 7.16 | K12: =Hoja2!K12/Hoja2!$B$105 -> 6.53 | ... O12: =Hoja2!O12/Hoja2!$B$105 -> 2.14 | P12: 12.4 | Q12: 12.8 | R12: 14.5 | S12: 15.8 | T12: 18.7 | U12: 22.4 | V12: 24.3 | W12: 24.8 | X12: 22.8 | Y12: 19.6 | Z12: 15.4 | AA12: 13.1
A13: Castellón | B13: =-(0+2/60+9/3600) -> -0.035833333 | C13: =39+59/60+9/3600 -> 39.985833 | D13: =Hoja2!D13/Hoja2!$B$105 -> 1.96 | E13: =Hoja2!E13/Hoja2!$B$105 -> 2.69 | F13: =Hoja2!F13/Hoja2!$B$105 -> 3.88 | G13: =Hoja2!G13/Hoja2!$B$105 -> 4.85 | H13: =Hoja2!H13/Hoja2!$B$105 -> 5.86 | I13: =Hoja2!I13/Hoja2!$B$105 -> 6.38 | J13: =Hoja2!J13/Hoja2!$B$105 -> 6.39 | K13: =Hoja2!K13/Hoja2!$B$105 -> 5.65 | ... O13: =Hoja2!O13/Hoja2!$B$105 -> 1.68 | P13: 11 | Q13: 11.3 | R13: 13.1 | S13: 15 | T13: 17.8 | U13: 21.8 | V13: 24.6 | W13: 25.1 | X13: 22.8 | Y13: 19.8 | Z13: 15.2 | AA13: 11.8
A14: Ceuta | B14: =-(5+18/60+58/3600) -> -5.3161111 | C14: =35+53/60+17/3600 -> 35.888056 | D14: =Hoja2!D14/Hoja2!$B$105 -> 2.53 | E14: =Hoja2!E14/Hoja2!$B$105 -> 3.11 | F14: =Hoja2!F14/Hoja2!$B$105 -> 4.48 | G14: =Hoja2!G14/Hoja2!$B$105 -> 5.27 | H14: =Hoja2!H14/Hoja2!$B$105 -> 6.55 | I14: =Hoja2!I14/Hoja2!$B$105 -> 7.13 | J14: =Hoja2!J14/Hoja2!$B$105 -> 6.85 | K14: =Hoja2!K14/Hoja2!$B$105 -> 6.26 | ... O14: =Hoja2!O14/Hoja2!$B$105 -> 2.16 | P14: 14.3 | Q14: 14.4 | R14: 15 | S14: 15.7 | T14: 17.5 | U14: 20.1 | V14: 21.9 | W14: 22.6 | X14: 21.5 | Y14: 19.6 | Z14: 16.9 | AA14: 15.1
A15: Ciudad Real | B15: =-(3+55/60+38/3600) -> -3.9272222 | C15: =38+59/60+9/3600 -> 38.985833 | D15: =Hoja2!D15/Hoja2!$B$105 -> 2.27 | E15: =Hoja2!E15/Hoja2!$B$105 -> 2.99 | F15: =Hoja2!F15/Hoja2!$B$105 -> 4.62 | G15: =Hoja2!G15/Hoja2!$B$105 -> 5.27 | H15: =Hoja2!H15/Hoja2!$B$105 -> 6.61 | I15: =Hoja2!I15/Hoja2!$B$105 -> 7.22 | J15: =Hoja2!J15/Hoja2!$B$105 -> 7.2 | K15: =Hoja2!K15/Hoja2!$B$105 -> 6.39 | ... O15: =Hoja2!O15/Hoja2!$B$105 -> 1.9 | P15: 5 | Q15: 6.8 | R15: 9.9 | S15: 12.5 | T15: 16.9 | U15: 23 | V15: 26 | W15: 25.8 | X15: 21 | Y15: 15.4 | Z15: 9.1 | AA15: 6
A16: Córdoba | B16: =-(4+46/60+44/3600) -> -4.7788889 | C16: =37+53/60+5/3600 -> 37.884722 | D16: =Hoja2!D16/Hoja2!$B$105 -> 2.44 | E16: =Hoja2!E16/Hoja2!$B$105 -> 3.11 | F16: =Hoja2!F16/Hoja2!$B$105 -> 4.59 | G16: =Hoja2!G16/Hoja2!$B$105 -> 5.18 | H16: =Hoja2!H16/Hoja2!$B$105 -> 6.62 | I16: =Hoja2!I16/Hoja2!$B$105 -> 7.18 | J16: =Hoja2!J16/Hoja2!$B$105 -> 6.97 | K16: =Hoja2!K16/Hoja2!$B$105 -> 6.15 | ... O16: =Hoja2!O16/Hoja2!$B$105 -> 2.03 | P16: 8.7 | Q16: 10.1 | R16: 13.1 | S16: 15.6 | T16: 19.7 | U16: 25.4 | V16: 28.1 | W16: 28.1 | X16: 23.8 | Y16: 18.6 | Z16: 12.7 | AA16: 9.6
A17: Cuenca | B17: =-(2+8/60+2/3600) -> -2.1338889 | C17: =40+4/60+18/3600 -> 40.071667 | D17: =Hoja2!D18/Hoja2!$B$105 -> 2.17 | E17: =Hoja2!E18/Hoja2!$B$105 -> 2.89 | F17: =Hoja2!F18/Hoja2!$B$105 -> 4.47 | G17: =Hoja2!G18/Hoja2!$B$105 -> 5.29 | H17: =Hoja2!H18/Hoja2!$B$105 -> 6.55 | I17: =Hoja2!I18/Hoja2!$B$105 -> 7.08 | J17: =Hoja2!J18/Hoja2!$B$105 -> 7.14 | K17: =Hoja2!K18/Hoja2!$B$105 -> 6.3 | ... O17: =Hoja2!O18/Hoja2!$B$105 -> 1.85 | P17: 3.2 | Q17: 4.5 | R17: 7.6 | S17: 10.1 | T17: 14.2 | U17: 19.8 | V17: 23.1 | W17: 22.9 | X17: 18.2 | Y17: 12.9 | Z17: 7 | AA17: 4
A18: Gerona | B18: =(2+49/60+25/3600) -> 2.8236111 | C18: =41+58/60+54/3600 -> 41.981667 | D18: =Hoja2!D19/Hoja2!$B$105 -> 1.87 | E18: =Hoja2!E19/Hoja2!$B$105 -> 2.54 | F18: =Hoja2!F19/Hoja2!$B$105 -> 3.92 | G18: =Hoja2!G19/Hoja2!$B$105 -> 4.87 | H18: =Hoja2!H19/Hoja2!$B$105 -> 5.8 | I18: =Hoja2!I19/Hoja2!$B$105 -> 6.59 | J18: =Hoja2!J19/Hoja2!$B$105 -> 6.8 | K18: =Hoja2!K19/Hoja2!$B$105 -> 5.82 | ... O18: =Hoja2!O19/Hoja2!$B$105 -> 1.63 | P18: 7.9 | Q18: 8.3 | R18: 11.1 | S18: 13.7 | T18: 17.2 | U18: 21.6 | V18: 24.1 | W18: 24.3 | X18: 20.5 | Y18: 17.1 | Z18: 11.9 | AA18: 8.5
A19: Granada | B19: =-(3+35/60+52/3600) -> -3.5977778 | C19: =37+10/60+35/3600 -> 37.176389 | D19: =Hoja2!D20/Hoja2!$B$105 -> 2.6 | E19: =Hoja2!E20/Hoja2!$B$105 -> 3.25 | F19: =Hoja2!F20/Hoja2!$B$105 -> 4.73 | G19: =Hoja2!G20/Hoja2!$B$105 -> 5.46 | H19: =Hoja2!H20/Hoja2!$B$105 -> 6.75 | I19: =Hoja2!I20/Hoja2!$B$105 -> 7.26 | J19: =Hoja2!J20/Hoja2!$B$105 -> 7.18 | K19: =Hoja2!K20/Hoja2!$B$105 -> 6.27 | ... O19: =Hoja2!O20/Hoja2!$B$105 -> 2.2 | P19: 6.2 | Q19: 7.4 | R19: 10.3 | S19: 12.9 | T19: 17.1 | U19: 23.2 | V19: 26.9 | W19: 26.5 | X19: 21.3 | Y19: 15.69 | Z19: 9.8 | AA19: 7.2
A20: Guadalajara | B20: =-(3+9/60+57/3600) -> -3.1658333 | C20: =40+37/60+48/3600 -> 40.63 | D20: =Hoja2!D21/Hoja2!$B$105 -> 1.99 | E20: =Hoja2!E21/Hoja2!$B$105 -> 2.72 | F20: =Hoja2!F21/Hoja2!$B$105 -> 4.42 | G20: =Hoja2!G21/Hoja2!$B$105 -> 5.15 | H20: =Hoja2!H21/Hoja2!$B$105 -> 6.52 | I20: =Hoja2!I21/Hoja2!$B$105 -> 7.18 | J20: =Hoja2!J21/Hoja2!$B$105 -> 7.27 | K20: =Hoja2!K21/Hoja2!$B$105 -> 6.34 | ... O20: =Hoja2!O21/Hoja2!$B$105 -> 1.64 | P20: 4 | Q20: 5.6 | R20: 8.6 | S20: 11 | T20: 15.4 | U20: 21.2 | V20: 24.4 | W20: 24 | X20: 19.7 | Y20: 14 | Z20: 7.9 | AA20: 4.6
A21: Huelva | B21: =-(6+56/60+58/3600) -> -6.9494444 | C21: =37+15/60+25/3600 -> 37.256944 | D21: =Hoja2!D22/Hoja2!$B$105 -> 2.51 | E21: =Hoja2!E22/Hoja2!$B$105 -> 3.09 | F21: =Hoja2!F22/Hoja2!$B$105 -> 4.59 | G21: =Hoja2!G22/Hoja2!$B$105 -> 5.39 | H21: =Hoja2!H22/Hoja2!$B$105 -> 6.84 | I21: =Hoja2!I22/Hoja2!$B$105 -> 7.24 | J21: =Hoja2!J22/Hoja2!$B$105 -> 7.27 | K21: =Hoja2!K22/Hoja2!$B$105 -> 6.57 | ... O21: =Hoja2!O22/Hoja2!$B$105 -> 2.12 | P21: 10.6 | Q21: 11.7 | R21: 14.1 | S21: 15.8 | T21: 19.1 | U21: 2.7 | V21: 25.4 | W21: 26.1 | X21: 22.7 | Y21: 19.1 | Z21: 14.3 | AA21: 11.6
A22: Huesca | B22: =-(0+24/60+32/3600) -> -0.40888889 | C22: =42+8/60+24/3600 -> 42.14 | D22: =Hoja2!D23/Hoja2!$B$105 -> 1.72 | E22: =Hoja2!E23/Hoja2!$B$105 -> 2.47 | F22: =Hoja2!F23/Hoja2!$B$105 -> 3.84 | G22: =Hoja2!G23/Hoja2!$B$105 -> 4.68 | H22: =Hoja2!H23/Hoja2!$B$105 -> 5.62 | I22: =Hoja2!I23/Hoja2!$B$105 -> 6.31 | J22: =Hoja2!J23/Hoja2!$B$105 -> 6.34 | K22: =Hoja2!K23/Hoja2!$B$105 -> 5.58 | ... O22: =Hoja2!O23/Hoja2!$B$105 -> 1.53 | P22: 5.5 | Q22: 6.5 | R22: 9.5 | S22: 12 | T22: 16.5 | U22: 21.5 | V22: 23.8 | W22: 23.5 | X22: 19.3 | Y22: 15.1 | Z22: 9.2 | AA22: 6
A23: Jaén | B23: =-(3+47/60+22/3600) -> -3.7894444 | C23: =37+45/60+56/3600 -> 37.765556 | D23: =Hoja2!D24/Hoja2!$B$105 -> 2.47 | E23: =Hoja2!E24/Hoja2!$B$105 -> 3.18 | F23: =Hoja2!F24/Hoja2!$B$105 -> 4.72 | G23: =Hoja2!G24/Hoja2!$B$105 -> 5.34 | H23: =Hoja2!H24/Hoja2!$B$105 -> 6.62 | I23: =Hoja2!I24/Hoja2!$B$105 -> 7.18 | J23: =Hoja2!J24/Hoja2!$B$105 -> 7.04 | K23: =Hoja2!K24/Hoja2!$B$105 -> 6.22 | ... O23: =Hoja2!O24/Hoja2!$B$105 -> 2.1 | P23: 7.3 | Q23: 8.7 | R23: 11.7 | S23: 14.1 | T23: 18.1 | U23: 23.7 | V23: 26.8 | W23: 26.7 | X23: 22 | Y23: 16.7 | Z23: 10.8 | AA23: 8
A24: La Coruña | B24: =-(8+23/60+45/3600) -> -8.3958333 | C24: =43+22/60+15/3600 -> 43.370833 | D24: =Hoja2!D17/Hoja2!$B$105 -> 1.43 | E24: =Hoja2!E17/Hoja2!$B$105 -> 2.06 | F24: =Hoja2!F17/Hoja2!$B$105 -> 3.58 | G24: =Hoja2!G17/Hoja2!$B$105 -> 4.08 | H24: =Hoja2!H17/Hoja2!$B$105 -> 4.87 | I24: =Hoja2!I17/Hoja2!$B$105 -> 5.62 | J24: =Hoja2!J17/Hoja2!$B$105 -> 5.32 | K24: =Hoja2!K17/Hoja2!$B$105 -> 4.96 | ... O24: =Hoja2!O17/Hoja2!$B$105 -> 1.11 | P24: 9.3 | Q24: 9.1 | R24: 11 | S24: 12.2 | T24: 14.2 | U24: 16.7 | V24: 18.5 | W24: 19 | X24: 18.3 | Y24: 15.3 | Z24: 11.6 | AA24: 9.7
A25: Las P. de Gran Canaria | B25: =-(15+25/60+48/3600) -> -15.43 | C25: =28+7/60+29/3600 -> 28.124722 | D25: 3.57 | E25: 4.41 | F25: 5.58 | G25: 6.44 | H25: 6.98 | I25: 6.83 | J25: 6.5 | K25: 6.54 | L25: 6 | M25: 4.92 | N25: 3.74 | O25: 3.28 | P25: 17.6 | Q25: 17.1 | R25: 17.3 | S25: 17.6 | T25: 18.5 | U25: 19.9 | V25: 21.2 | W25: 22 | X25: 22.2 | Y25: 21.6 | Z25: 20.4 | AA25: 19 | AB25: NASA
A26: León | B26: =-(5+34/60+18/3600) -> -5.5716667 | C26: =42+35/60+59/3600 -> 42.599722 | D26: =Hoja2!D26/Hoja2!$B$105 -> 1.68 | E26: =Hoja2!E26/Hoja2!$B$105 -> 2.41 | F26: =Hoja2!F26/Hoja2!$B$105 -> 3.9 | G26: =Hoja2!G26/Hoja2!$B$105 -> 4.61 | H26: =Hoja2!H26/Hoja2!$B$105 -> 5.53 | I26: =Hoja2!I26/Hoja2!$B$105 -> 6.26 | J26: =Hoja2!J26/Hoja2!$B$105 -> 6.28 | K26: =Hoja2!K26/Hoja2!$B$105 -> 5.63 | ... O26: =Hoja2!O26/Hoja2!$B$105 -> 1.32 | P26: 3.1 | Q26: 4 | R26: 6.7 | S26: 8.7 | T26: 12.7 | U26: 17.4 | V26: 19.5 | W26: 19.6 | X26: 16.4 | Y26: 11.4 | Z26: 6.2 | AA26: 3.5
A27: Lérida | B27: =(0+37/60+32/3600) -> 0.62555556 | C27: =41+36/60+50/3600 -> 41.613889 | D27: =Hoja2!D27/Hoja2!$B$105 -> 1.82 | E27: =Hoja2!E27/Hoja2!$B$105 -> 2.55 | F27: =Hoja2!F27/Hoja2!$B$105 -> 3.89 | G27: =Hoja2!G27/Hoja2!$B$105 -> 4.8 | H27: =Hoja2!H27/Hoja2!$B$105 -> 5.73 | I27: =Hoja2!I27/Hoja2!$B$105 -> 6.32 | J27: =Hoja2!J27/Hoja2!$B$105 -> 6.38 | K27: =Hoja2!K27/Hoja2!$B$105 -> 5.61 | ... O27: =Hoja2!O27/Hoja2!$B$105 -> 1.59 | P27: 7.2 | Q27: 8.1 | R27: 11.4 | S27: 14 | T27: 18.1 | U27: 22.5 | V27: 24.9 | W27: 25.1 | X27: 20.9 | Y27: 17 | Z27: 11.2 | AA27: 7.6
A28: Logroño | B28: =-(2+26/60+59/3600) -> -2.4497222 | C28: =42+27/60+56/3600 -> 42.465556 | D28: =Hoja2!D28/Hoja2!$B$105 -> 1.65 | E28: =Hoja2!E28/Hoja2!$B$105 -> 2.4 | F28: =Hoja2!F28/Hoja2!$B$105 -> 3.86 | G28: =Hoja2!G28/Hoja2!$B$105 -> 4.66 | H28: =Hoja2!H28/Hoja2!$B$105 -> 5.77 | I28: =Hoja2!I28/Hoja2!$B$105 -> 6.4 | J28: =Hoja2!J28/Hoja2!$B$105 -> 6.41 | K28: =Hoja2!K28/Hoja2!$B$105 -> 5.66 | ... O28: =Hoja2!O28/Hoja2!$B$105 -> 1.39 | P28: 5.9 | Q28: 6.5 | R28: 9.3 | S28: 11.4 | T28: 15.3 | U28: 19.4 | V28: 21.4 | W28: 21.8 | X28: 18.6 | Y28: 15 | Z28: 9.1 | AA28: 6
A29: Lugo | B29: =-(7+33/60+21/3600) -> -7.5558333 | C29: =43+0/60+43/3600 -> 43.011944 | D29: =Hoja2!D29/Hoja2!$B$105 -> 1.56 | E29: =Hoja2!E29/Hoja2!$B$105 -> 2.2 | F29: =Hoja2!F29/Hoja2!$B$105 -> 3.68 | G29: =Hoja2!G29/Hoja2!$B$105 -> 4.22 | H29: =Hoja2!H29/Hoja2!$B$105 -> 5.04 | I29: =Hoja2!I29/Hoja2!$B$105 -> 5.78 | J29: =Hoja2!J29/Hoja2!$B$105 -> 5.6 | K29: =Hoja2!K29/Hoja2!$B$105 -> 5.19 | ... O29: =Hoja2!O29/Hoja2!$B$105 -> 1.24 | P29: 6.2 | Q29: 6.4 | R29: 8.8 | S29: 10 | T29: 12.7 | U29: 16.5 | V29: 17.6 | W29: 18.3 | X29: 16.8 | Y29: 13.4 | Z29: 8.7 | AA29: 6.4
A30: Madrid | B30: =-(3+42/60+1/3600) -> -3.7002778 | C30: =40+25/60+0/3600 -> 40.416667 | D30: =Hoja2!D30/Hoja2!$B$105 -> 2 | E30: =Hoja2!E30/Hoja2!$B$105 -> 2.73 | F30: =Hoja2!F30/Hoja2!$B$105 -> 4.48 | G30: =Hoja2!G30/Hoja2!$B$105 -> 5.17 | H30: =Hoja2!H30/Hoja2!$B$105 -> 6.58 | I30: =Hoja2!I30/Hoja2!$B$105 -> 7.24 | J30: =Hoja2!J30/Hoja2!$B$105 -> 7.32 | K30: =Hoja2!K30/Hoja2!$B$105 -> 6.41 | ... O30: =Hoja2!O30/Hoja2!$B$105 -> 1.64 | P30: 4.1 | Q30: 5.5 | R30: 9.1 | S30: 11.6 | T30: 16.3 | U30: 22.5 | V30: 25.3 | W30: 24.8 | X30: 20.4 | Y30: 14.1 | Z30: 8.2 | AA30: 4.7
A31: Málaga | B31: =-(4+25/60+12/3600) -> -4.42 | C31: =36+43/60+10/3600 -> 36.719444 | D31: =Hoja2!D31/Hoja2!$B$105 -> 2.49 | E31: =Hoja2!E31/Hoja2!$B$105 -> 3.13 | F31: =Hoja2!F31/Hoja2!$B$105 -> 4.4 | G31: =Hoja2!G31/Hoja2!$B$105 -> 5.17 | H31: =Hoja2!H31/Hoja2!$B$105 -> 6.46 | I31: =Hoja2!I31/Hoja2!$B$105 -> 7.11 | J31: =Hoja2!J31/Hoja2!$B$105 -> 6.88 | K31: =Hoja2!K31/Hoja2!$B$105 -> 6.04 | ... O31: =Hoja2!O31/Hoja2!$B$105 -> 2.07 | P31: 12.5 | Q31: 13.3 | R31: 14.5 | S31: 15.6 | T31: 17.9 | U31: 20.9 | V31: 23.7 | W31: 24.2 | X31: 22.1 | Y31: 19.1 | Z31: 15.5 | AA31: 13.4
A32: Melilla | B32: =-(2+56/60+19/3600) -> -2.9386111 | C32: =35+17/60+32/3600 -> 35.292222 | D32: =Hoja2!D32/Hoja2!$B$105 -> 2.61 | E32: =Hoja2!E32/Hoja2!$B$105 -> 3.34 | F32: =Hoja2!F32/Hoja2!$B$105 -> 4.53 | G32: =Hoja2!G32/Hoja2!$B$105 -> 5.37 | H32: =Hoja2!H32/Hoja2!$B$105 -> 6.53 | I32: =Hoja2!I32/Hoja2!$B$105 -> 7.01 | J32: =Hoja2!J32/Hoja2!$B$105 -> 6.89 | K32: =Hoja2!K32/Hoja2!$B$105 -> 6.05 | ... O32: =Hoja2!O32/Hoja2!$B$105 -> 2.37 | P32: 13.3 | Q32: 13.6 | R32: 14.7 | S32: 15.9 | T32: 18 | U32: 21.1 | V32: 23.2 | W32: 24.2 | X32: 22.5 | Y32: 20.1 | Z32: 16.7 | AA32: 14.5
A33: Murcia | B33: =-(1+7/60+47/3600) -> -1.1297222 | C33: =37+59/60+0/3600 -> 37.983333 | D33: =Hoja2!D33/Hoja2!$B$105 -> 2.44 | E33: =Hoja2!E33/Hoja2!$B$105 -> 3.21 | F33: =Hoja2!F33/Hoja2!$B$105 -> 4.55 | G33: =Hoja2!G33/Hoja2!$B$105 -> 5.41 | H33: =Hoja2!H33/Hoja2!$B$105 -> 6.48 | I33: =Hoja2!I33/Hoja2!$B$105 -> 7 | J33: =Hoja2!J33/Hoja2!$B$105 -> 7.05 | K33: =Hoja2!K33/Hoja2!$B$105 -> 6.15 | ... O33: =Hoja2!O33/Hoja2!$B$105 -> 2.16 | P33: 10.5 | Q33: 11.1 | R33: 13.3 | S33: 15.7 | T33: 19.1 | U33: 23.3 | V33: 25.7 | W33: 25.8 | X33: 22.9 | Y33: 19.5 | Z33: 14.5 | AA33: 11.2
A34: Orense | B34: =-(7+51/60+52/3600) -> -7.8644444 | C34: =42+20/60+23/3600 -> 42.339722 | D34: =Hoja2!D34/Hoja2!$B$105 -> 1.69 | E34: =Hoja2!E34/Hoja2!$B$105 -> 2.33 | F34: =Hoja2!F34/Hoja2!$B$105 -> 3.86 | G34: =Hoja2!G34/Hoja2!$B$105 -> 4.46 | H34: =Hoja2!H34/Hoja2!$B$105 -> 5.37 | I34: =Hoja2!I34/Hoja2!$B$105 -> 6.22 | J34: =Hoja2!J34/Hoja2!$B$105 -> 6 | K34: =Hoja2!K34/Hoja2!$B$105 -> 5.56 | ... O34: =Hoja2!O34/Hoja2!$B$105 -> 1.29 | P34: 7 | Q34: 8.5 | R34: 11.8 | S34: 13.8 | T34: 17.4 | U34: 22.2 | V34: 23.8 | W34: 24.3 | X34: 21.3 | Y34: 16.5 | Z34: 10.8 | AA34: 7.7
A35: Oviedo | B35: =-(5+50/60+41/3600) -> -5.8447222 | C35: =43+21/60+37/3600 -> 43.360278 | D35: =Hoja2!D35/Hoja2!$B$105 -> 1.51 | E35: =Hoja2!E35/Hoja2!$B$105 -> 2.09 | F35: =Hoja2!F35/Hoja2!$B$105 -> 3.44 | G35: =Hoja2!G35/Hoja2!$B$105 -> 4.07 | H35: =Hoja2!H35/Hoja2!$B$105 -> 4.85 | I35: =Hoja2!I35/Hoja2!$B$105 -> 5.34 | J35: =Hoja2!J35/Hoja2!$B$105 -> 5.23 | K35: =Hoja2!K35/Hoja2!$B$105 -> 4.73 | ... O35: =Hoja2!O35/Hoja2!$B$105 -> 1.23 | P35: 6.9 | Q35: 7.7 | R35: 10.7 | S35: 11.9 | T35: 15.1 | U35: 19.2 | V35: 20.6 | W35: 20.6 | X35: 18.4 | Y35: 15.2 | Z35: 10.4 | AA35: 7.6
A36: Palencia | B36: =-(4+31/60+52/3600) -> -4.5311111 | C36: =42+0/60+44/3600 -> 42.012222 | D36: =Hoja2!D36/Hoja2!$B$105 -> 1.71 | E36: =Hoja2!E36/Hoja2!$B$105 -> 2.55 | F36: =Hoja2!F36/Hoja2!$B$105 -> 4.1 | G36: =Hoja2!G36/Hoja2!$B$105 -> 4.91 | H36: =Hoja2!H36/Hoja2!$B$105 -> 6 | I36: =Hoja2!I36/Hoja2!$B$105 -> 6.72 | J36: =Hoja2!J36/Hoja2!$B$105 -> 6.8 | K36: =Hoja2!K36/Hoja2!$B$105 -> 5.99 | ... O36: =Hoja2!O36/Hoja2!$B$105 -> 1.33 | P36: 3.5 | Q36: 4.4 | R36: 7.4 | S36: 9.5 | T36: 13.5 | U36: 18.5 | V36: 20.5 | W36: 20.6 | X36: 17.2 | Y36: 12.4 | Z36: 6.9 | AA36: 3.7
A37: Palma de Mallorca | B37: =2+38/60+59/3600 -> 2.6497222 | C37: =39+34/60+10/3600 -> 39.569444 | D37: =Hoja2!D37/Hoja2!$B$105 -> 2.06 | E37: =Hoja2!E37/Hoja2!$B$105 -> 2.73 | F37: =Hoja2!F37/Hoja2!$B$105 -> 4.01 | G37: =Hoja2!G37/Hoja2!$B$105 -> 5.12 | H37: =Hoja2!H37/Hoja2!$B$105 -> 6.18 | I37: =Hoja2!I37/Hoja2!$B$105 -> 6.72 | J37: =Hoja2!J37/Hoja2!$B$105 -> 6.73 | K37: =Hoja2!K37/Hoja2!$B$105 -> 5.93 | ... O37: =Hoja2!O37/Hoja2!$B$105 -> 1.81 | P37: 11 | Q37: 10.9 | R37: 12.7 | S37: 15.2 | T37: 18.3 | U37: 22.2 | V37: 25 | W37: 25.5 | X37: 22.5 | Y37: 19.7 | Z37: 15.3 | AA37: 12.2
A38: Pamplona | B38: =-(1+38/60+39/3600) -> -1.6441667 | C38: =42+49/60+4/3600 -> 42.817778 | D38: =Hoja2!D38/Hoja2!$B$105 -> 1.56 | E38: =Hoja2!E38/Hoja2!$B$105 -> 2.33 | F38: =Hoja2!F38/Hoja2!$B$105 -> 3.7 | G38: =Hoja2!G38/Hoja2!$B$105 -> 4.59 | H38: =Hoja2!H38/Hoja2!$B$105 -> 5.55 | I38: =Hoja2!I38/Hoja2!$B$105 -> 6.28 | J38: =Hoja2!J38/Hoja2!$B$105 -> 6.26 | K38: =Hoja2!K38/Hoja2!$B$105 -> 5.57 | ... O38: =Hoja2!O38/Hoja2!$B$105 -> 1.38 | P38: 4.9 | Q38: 5.5 | R38: 8.5 | S38: 10.7 | T38: 14.5 | U38: 18.6 | V38: 20.5 | W38: 21 | X38: 17.7 | Y38: 14.1 | Z38: 8.4 | AA38: 5.2
A39: Pontevedra | B39: =-(8+38/60+53/3600) -> -8.6480556 | C39: =42+26/60+1/3600 -> 42.433611 | D39: =Hoja2!D39/Hoja2!$B$105 -> 1.74 | E39: =Hoja2!E39/Hoja2!$B$105 -> 2.4 | F39: =Hoja2!F39/Hoja2!$B$105 -> 3.92 | G39: =Hoja2!G39/Hoja2!$B$105 -> 4.68 | H39: =Hoja2!H39/Hoja2!$B$105 -> 5.6 | I39: =Hoja2!I39/Hoja2!$B$105 -> 6.51 | J39: =Hoja2!J39/Hoja2!$B$105 -> 6.06 | K39: =Hoja2!K39/Hoja2!$B$105 -> 5.78 | ... O39: =Hoja2!O39/Hoja2!$B$105 -> 1.31 | P39: 9.6 | Q39: 9.7 | R39: 11.8 | S39: 13.3 | T39: 15.5 | U39: 18.1 | V39: 20 | W39: 20.4 | X39: 19.6 | Y39: 16.1 | Z39: 12 | AA39: 10.1
A40: Salamanca | B40: =-(5+39/60+46/3600) -> -5.6627778 | C40: =40+57/60+53/3600 -> 40.964722 | D40: =Hoja2!D40/Hoja2!$B$105 -> 1.9 | E40: =Hoja2!E40/Hoja2!$B$105 -> 2.69 | F40: =Hoja2!F40/Hoja2!$B$105 -> 4.41 | G40: =Hoja2!G40/Hoja2!$B$105 -> 4.96 | H40: =Hoja2!H40/Hoja2!$B$105 -> 6.3 | I40: =Hoja2!I40/Hoja2!$B$105 -> 7.15 | J40: =Hoja2!J40/Hoja2!$B$105 -> 7.21 | K40: =Hoja2!K40/Hoja2!$B$105 -> 6.47 | ... O40: =Hoja2!O40/Hoja2!$B$105 -> 1.46 | P40: 3.5 | Q40: 4.6 | R40: 7.8 | S40: 9.8 | T40: 13.9 | U40: 19.3 | V40: 21.6 | W40: 21.6 | X40: 17.9 | Y40: 12.5 | Z40: 7.1 | AA40: 4.2
...

Sheet Hoja2
D1: Radiación Global Mensual en plano Horizontal (Wh/m^2/día)
A2: Ciudad | B2: Latitud | C2: Longitud | D2: Enero | E2: Febrero | F2: Marzo | G2: Abril | H2: Mayo | I2: Junio | J2: Julio | K2: Agosto | L2: Septiembre | M2: Octubre | N2: Noviembre | O2: Diciembre
A3: Albacete | B3: 38°59'51" North | C3: 1°51'36" West | D3: 2330 | E3: 3060 | F3: 4460 | G3: 5330 | H3: 6480 | I3: 7060 | J3: 7090 | K3: 6280 | L3: 5050 | M3: 3660 | N3: 2450 | O3: 2000
A4: Alicante | B4: 38°20'42" North | C4: 0°28'51" West | D4: 2320 | E4: 3090 | F4: 4340 | G4: 5260 | H4: 6370 | I4: 6890 | J4: 6910 | K4: 6090 | L4: 4930 | M4: 3710 | N4: 2380 | O4: 2070
A5: Almería | B5: 36°50'24" North | C5: 2°28'4" West | D5: 2490 | E5: 3210 | F5: 4470 | G5: 5290 | H5: 6420 | I5: 6940 | J5: 6890 | K5: 6050 | L5: 4900 | M5: 3760 | N5: 2530 | O5: 2180
A6: Ávila | B6: 40°39'23" North | C6: 4°42'1" West | D6: 2000 | E6: 2780 | F6: 4560 | G6: 5240 | H6: 6590 | I6: 7280 | J6: 7390 | K6: 6550 | L6: 4950 | M6: 3400 | N6: 2120 | O6: 1600
A7: Badajoz | B7: 38°52'42" North | C7: 6°58'12" West | D7: 2230 | E7: 2880 | F7: 4720 | G7: 5130 | H7: 6610 | I7: 7250 | J7: 7220 | K7: 6650 | L7: 5100 | M7: 3680 | N7: 2320 | O7: 1930
A8: Barcelona | B8: 41°23'16" North | C8: 2°10'11" East | D8: 1890 | E8: 2560 | F8: 3910 | G8: 4900 | H8: 5840 | I8: 6550 | J8: 6580 | K8: 5780 | L8: 4530 | M8: 3160 | N8: 2040 | O8: 1680
A9: Bilbao | B9: 43°15'25" North | C9: 2°55'24" West | D9: 1430 | E9: 2120 | F9: 3500 | G9: 4300 | H9: 5300 | I9: 5860 | J9: 5840 | K9: 5140 | L9: 4160 | M9: 2720 | N9: 1640 | O9: 1230
A10: Burgos | B10: 42°20'27" North | C10: 3°41'59" West | D10: 1700 | E10: 2530 | F10: 4060 | G10: 4880 | H10: 6010 | I10: 6670 | J10: 6750 | K10: 5900 | L10: 4620 | M10: 3100 | N10: 1880 | O10: 1370
A11: Cáceres | B11: 39°28'34" North | C11: 6°22'14" West | D11: 2120 | E11: 2810 | F11: 4620 | G11: 5010 | H11: 6480 | I11: 7200 | J11: 7180 | K11: 6560 | L11: 4980 | M11: 3500 | N11: 2240 | O11: 1770
A12: Cádiz | B12: 36°31'46" North | C12: 6°17'33" West | D12: 2550 | E12: 3160 | F12: 4590 | G12: 5400 | H12: 6760 | I12: 7280 | J12: 7160 | K12: 6530 | L12: 5200 | M12: 3930 | N12: 2540 | O12: 2140
A13: Castellón | B13: 39°59'9" North | C13: 0°2'9" West | D13: 1960 | E13: 2690 | F13: 3880 | G13: 4850 | H13: 5860 | I13: 6380 | J13: 6390 | K13: 5650 | L13: 4570 | M13: 3300 | N13: 2140 | O13: 1680
A14: Ceuta | B14: 35°53'17" North | C14: 5°18'58" West | D14: 2530 | E14: 3110 | F14: 4480 | G14: 5270 | H14: 6550 | I14: 7130 | J14: 6850 | K14: 6260 | L14: 4960 | M14: 3850 | N14: 2470 | O14: 2160
... A54: Zaragoza | B54: 41°39'24" North | C54: 0°52'47" West | D54: 1780 | E54: 2500 | F54: 3890 | G54: 4750 | H54: 5760 | I54: 6390 | J54: 6400 | K54: 5580 | L54: 4530 | M54: 3070 | N54: 1980 | O54: 1520
A55: Capitales Europeas
A56: Amsterdam | B56: 52°22'12" North | C56: 4°53'42" East | D56: 597 | E56: 1370 | F56: 2200 | G56: 3750 | H56: 4900 | I56: 4900 | J56: 4930 | K56: 4160 | L56: 2770 | M56: 1600 | N56: 800 | O56: 449
A57: Atenas | B57: 37°59'1" North | C57: 23°43'45" East | D57: 2060 | E57: 2640 | F57: 3870 | G57: 5240 | H57: 6240 | I57: 7040 | J57: 6950 | K57: 6230 | L57: 5110 | M57: 3420 | N57: 2170 | O57: 1760
A58: Berlín | B58: 52°31'9" North | C58: 13°24'21" East | D58: 630 | E58: 1340 | F58: 2220 | G58: 3660 | H58: 5030 | I58: 4840 | J58: 5010 | K58: 4300 | L58: 2800 | M58: 1670 | N58: 799 | O58: 454
A59: Bruselas | B59: 50°51'1" North | C59: 4°21'6" East | D59: 635 | E59: 1380 | F59: 2150 | G59: 3510 | H59: 4520 | I59: 4620 | J59: 4840 | K59: 4080 | L59: 2740 | M59: 1670 | N59: 864 | O59: 494
A60: Bucarest | B60: 44°26'15" North | C60: 26°5'50" East | D60: 1330 | E60: 2040 | F60: 3150 | G60: 4500 | H60: 5660 | I60: 6000 | J60: 6110 | K60: 5550 | L60: 4270 | M60: 2900 | N60: 1500 | O60: 1090
A61: Budapest | B61: 47°29'54" North | C61: 19°2'26" East | D61: 922 | E61: 1610 | F61: 2780 | G61: 4230 | H61: 5310 | I61: 5800 | J61: 6060 | K61: 5010 | L61: 3620 | M61: 2220 | N61: 1140 | O61: 672
A62: Estocolmo | B62: 59°19'44" North | C62: 18°3'53" East | D62: 299 | E62: 907 | F62: 1980 | G62: 3590 | H62: 5300 | I62: 5360 | J62: 5200 | K62: 3870 | L62: 2450 | M62: 1160 | N62: 445 | O62: 175
A63: Helsinki | B63: 60°9'59" North | C63: 24°56'36" East | D63: 257 | E63: 917 | F63: 2010 | G63: 3710 | H63: 5190 | I63: 5620 | J63: 5460 | K63: 3830 | L63: 2190 | M63: 993 | N63: 329 | O63: 144
A64: Lisboa | B64: 38°43'25" North | C64: 9°8'23" West | D64: 2140 | E64: 2720 | F64: 4360 | G64: 5070 | H64: 6140 | I64: 6900 | J64: 7050 | K64: 6420 | L64: 5070 | M64: 3580 | N64: 2270 | O64: 1900
A65: Londres | B65: 51°30'26" North | C65: 0°7'39" West | D65: 736 | E65: 1350 | F65: 2210 | G65: 3650 | H65: 4640 | I65: 4800 | J65: 4840 | K65: 4150 | L65: 2790 | M65: 1700 | N65: 898 | O65: 524
A66: Luxemburgo | B66: 49°48'54" North | C66: 6°7'46" East | D66: 680 | E66: 1530 | F66: 2340 | G66: 3760 | H66: 4690 | I66: 4910 | J66: 5290 | K66: 4340 | L66: 3030 | M66: 1770 | N66: 949 | O66: 545
A67: Oslo | B67: 59°54'49" North | C67: 10°45'8" East | D67: 258 | E67: 772 | F67: 1710 | G67: 3190 | H67: 4550 | I67: 5170 | J67: 4750 | K67: 3500 | L67: 2210 | M67: 1000 | N67: 370 | O67: 177
... A73: Viena | B73: 48°12'29" North | C73: 16°22'25" East | D73: 924 | E73: 1600 | F73: 2720 | G73: 4080 | H73: 5120 | I73: 5500 | J73: 5700 | K73: 4710 | L73: 3390 | M73: 2110 | N73: 1050 | O73: 691
A74: Ciuadades Africanas
A75: Ciudad del Cabo | B75: 33°55'29" South | C75: 18°25'26" East | D75: 8380 | E75: 7550 | F75: 6110 | G75: 4370 | H75: 3250 | I75: 2760 | J75: 2940 | K75: 3810 | L75: 5040 | M75: 6650 | N75: 7810 | O75: 8430
A76: Dakar | B76: 14°41'34" North | C76: 17°26'48" West | D76: 5200 | E76: 5800 | F76: 6700 | G76: 7060 | H76: 7060 | I76: 7000 | J76: 6330 | K76: 5740 | L76: 5600 | M76: 5790 | N76: 5420 | O76: 5180
A77: El Cairo | B77: 30°2'39" North | C77: 31°14'8" East | D77: 2990 | E77: 3430 | F77: 4470 | G77: 5540 | H77: 6550 | I77: 7430 | J77: 6950 | K77: 6250 | L77: 5400 | M77: 4140 | N77: 3060 | O77: 2730
A78: Kinshasa | B78: 4°19'54" South | C78: 15°18'50" East | D78: 4980 | E78: 5080 | F78: 5260 | G78: 5110 | H78: 4910 | I78: 4700 | J78: 5280 | K78: 5400 | L78: 4910 | M78: 4570 | N78: 4810 | O78: 4790
A79: Nairobi | B79: 1°17'31" South | C79: 36°49'19" East | D79: 6600 | E79: 7010 | F79: 6730 | G79: 6020 | H79: 5350 | I79: 4700 | J79: 4330 | K79: 4620 | L79: 5850 | M79: 6110 | N79: 5830 | O79: 6270
A80: Rabat | B80: 34°0'54" North | C80: 6°49'57" West | D80: 3150 | E80: 4020 | F80: 5570 | G80: 6460 | H80: 7420 | I80: 7970 | J80: 7760 | K80: 7110 | L80: 5980 | M80: 4420 | N80: 3360 | O80: 2840
A81: Ciudades Asiáticas
A82: Bagdag | B82: 33°20'00"N | C82: 44°26'00" E | D82: =Hoja1!D89*$B$105 -> 2960 | E82: =Hoja1!E89*$B$105 -> 4030 | F82: =Hoja1!F89*$B$105 -> 4980 | G82: =Hoja1!G89*$B$105 -> 5390 | H82: =Hoja1!H89*$B$105 -> 6480 | I82: =Hoja1!I89*$B$105 -> 7560 | J82: =Hoja1!J89*$B$105 -> 7000 | K82: =Hoja1!K89*$B$105 -> 6710 | ... O82: =Hoja1!O89*$B$105 -> 2620
A83: Bangkok | B83: 13°45'08"N | C83: 100°29'38"E | D83: =Hoja1!D90*$B$105 -> 5070 | E83: =Hoja1!E90*$B$105 -> 5620 | F83: =Hoja1!F90*$B$105 -> 5990 | G83: =Hoja1!G90*$B$105 -> 6230 | H83: =Hoja1!H90*$B$105 -> 5370 | I83: =Hoja1!I90*$B$105 -> 4930 | J83: =Hoja1!J90*$B$105 -> 4820 | K83: =Hoja1!K90*$B$105 -> 4810 | ... O83: =Hoja1!O90*$B$105 -> 4860
A84: Moscú | B84: 55°48'34" North | C84: 37°36'55" East | D84: 485 | E84: 1230 | F84: 2460 | G84: 3450 | H84: 5280 | I84: 5290 | J84: 5160 | K84: 4180 | L84: 2460 | M84: 1280 | N84: 527 | O84: 332
...

Sheet Hoja3
